{"name": "test_square_numbers", "status": "skipped", "statusDetails": {"message": "XFAIL You are using wrong calculation\n\nAssertionError: assert 20 == (10 ** 2)", "trace": "self = <DemoThirdTest.test_xfail.TestMath object at 0x000002A2379EDBD0>\n\n    @pytest.mark.xfail(reason=\"You are using wrong calculation\")\n    def test_square_numbers(self):\n        num = 10\n        result = num + num\n>       assert  result == num ** 2\nE       assert 20 == (10 ** 2)\n\nDemoThirdTest\\test_xfail.py:16: AssertionError"}, "start": 1754971611438, "stop": 1754971611439, "uuid": "8aea739c-01f2-42c5-baac-2743c6c44310", "historyId": "b64e3271edf53800268817cfbd4c917a", "testCaseId": "b64e3271edf53800268817cfbd4c917a", "fullName": "DemoThirdTest.test_xfail.TestMath#test_square_numbers", "labels": [{"name": "parentSuite", "value": "DemoThirdTest"}, {"name": "suite", "value": "test_xfail"}, {"name": "subSuite", "value": "TestMath"}, {"name": "host", "value": "DESKTOP-0LJMU54"}, {"name": "thread", "value": "19604-MainThread"}, {"name": "framework", "value": "pytest"}, {"name": "language", "value": "cpython3"}, {"name": "package", "value": "DemoThirdTest.test_xfail"}], "titlePath": ["DemoThirdTest", "test_xfail.py", "TestMath"]}